from mcpi.minecraft import Minecraft
from mcpi import block
from time import sleep

def init():
    mc = Minecraft.create("127.0.0.1", 4711)
    x, y, z = mc.player.getPos()		
    return mc

def building(mc,x,y,z):
	print(x,y,z)
	mc.setBlocks(x-10,y,z-10,x+10,y+50,z+10,0)

	mc.setBlock(x+1, y, z, 1)
	mc.setBlock(x, y, z, 1)
	mc.setBlock(x, y, z+1, 1)
	mc.setBlock(x+2, y, z, 1)
	mc.setBlock(x, y, z+2, 1)
	mc.setBlock(x+3, y, z, 1)
	mc.setBlock(x, y, z+3, 1)
	mc.setBlock(x+4, y, z, 1)
	mc.setBlock(x, y, z+4, 1)

	mc.setBlock(x+5, y+1, z, 1)
	mc.setBlock(x+5, y+1, z, 1)
	mc.setBlock(x+5, y+1, z+1, 1)
	mc.setBlock(x+2, y+1, z, 1)
	mc.setBlock(x, y+1, z+2, 1)
	mc.setBlock(x+3, y+1, z, 1)
	mc.setBlock(x, y+1, z+3, 1)
	mc.setBlock(x+4, y+1, z, 1)
	mc.setBlock(x, y+1, z+4, 1)

	mc.setBlock(x+1, y+2, z, 1)
	mc.setBlock(x, y+2, z, 1)
	mc.setBlock(x, y+2, z+1, 1)
	mc.setBlock(x+2, y+2, z, 1)
	mc.setBlock(x, y+2, z+2, 1)
	mc.setBlock(x+3, y+2, z, 1)
	mc.setBlock(x, y+2, z+3, 1)
	mc.setBlock(x+4, y+2, z, 1)
	mc.setBlock(x, y+2, z+4, 1)

	mc.setBlock(x+1, y+3, z, 1)
	mc.setBlock(x, y+3, z, 1)
	mc.setBlock(x, y+3, z+1, 1)
	mc.setBlock(x+2, y+3, z, 1)
	mc.setBlock(x, y+3, z+2, 1)
	mc.setBlock(x+3, y+3, z, 1)
	mc.setBlock(x, y+3, z+3, 1)
	mc.setBlock(x+4, y+3, z, 1)
	mc.setBlock(x, y+3, z+4, 1)


	mc.setBlock(x+5, y, z, 1)
	mc.setBlock(x+5, y, z, 1)
	mc.setBlock(x+5, y, z+1, 1)
	mc.setBlock(x+5, y, z, 1)
	mc.setBlock(x+5, y, z+2, 1)
	mc.setBlock(x+5, y, z, 1)
	mc.setBlock(x+5, y, z+3, 1)
	mc.setBlock(x+5, y, z, 1)
	mc.setBlock(x+5, y, z+4, 1)

	mc.setBlock(x+5, y+1, z, 1)
	mc.setBlock(x+5, y+1, z, 1)
	mc.setBlock(x+5, y+1, z+1, 1)
	mc.setBlock(x+5, y+1, z, 1)
	mc.setBlock(x+5, y+1, z+2, 1)
	mc.setBlock(x+5, y+1, z, 1)
	mc.setBlock(x+5, y+1, z+3, 1)
	mc.setBlock(x+5, y+1, z, 1)
	mc.setBlock(x+5, y+1, z+4, 1)

	mc.setBlock(x+5, y+2, z, 1)
	mc.setBlock(x+5, y+2, z, 1)
	mc.setBlock(x+5, y+2, z+1, 1)
	mc.setBlock(x+5, y+2, z, 1)
	mc.setBlock(x+5, y+2, z+2, 1)
	mc.setBlock(x+5, y+2, z, 1)
	mc.setBlock(x+5, y+2, z+3, 1)
	mc.setBlock(x+5, y+2, z, 1)
	mc.setBlock(x+5, y+2, z+4, 1)

	mc.setBlock(x+5, y+3, z, 1)
	mc.setBlock(x+5, y+3, z, 1)
	mc.setBlock(x+5, y+3, z+1, 1)
	mc.setBlock(x+5, y+3, z, 1)
	mc.setBlock(x+5, y+3, z+2, 1)
	mc.setBlock(x+5, y+3, z, 1)
	mc.setBlock(x+5, y+3, z+3, 1)
	mc.setBlock(x+5, y+3, z, 1)
	mc.setBlock(x+5, y+3, z+4, 1)

	mc.setBlock(x+5, y+0, z+5, 1)
	mc.setBlock(x+5, y+3, z+5, 1)
	mc.setBlock(x+5, y+2, z+5, 1)
	mc.setBlock(x+5, y+1, z+5, 1)

	mc.setBlock(x+5, y+0, z+4, 1)
	mc.setBlock(x+5, y+3, z+4, 1)
	mc.setBlock(x+5, y+2, z+4, 1)
	mc.setBlock(x+5, y+1, z+4, 1)

	mc.setBlock(x+5, y+0, z+3, 1)
	mc.setBlock(x+5, y+3, z+3, 1)
	mc.setBlock(x+5, y+2, z+3, 1)
	mc.setBlock(x+5, y+1, z+3, 1)

	mc.setBlock(x+5, y+0, z+2, 1)
	mc.setBlock(x+5, y+3, z+2, 1)
	mc.setBlock(x+5, y+2, z+2, 1)
	mc.setBlock(x+5, y+1, z+2, 1)

	mc.setBlock(x+5, y+0, z+1, 1)
	mc.setBlock(x+5, y+3, z+1, 1)
	mc.setBlock(x+5, y+2, z+1, 1)
	mc.setBlock(x+5, y+1, z+1, 1)

	mc.setBlock(x+4, y+0, z+5, 1)
	mc.setBlock(x+4, y+3, z+5, 1)
	mc.setBlock(x+4, y+2, z+5, 1)
	mc.setBlock(x+4, y+1, z+5, 1)

	mc.setBlock(x+3, y+0, z+5, 1)
	mc.setBlock(x+3, y+3, z+5, 1)
	mc.setBlock(x+3, y+2, z+5, 1)
	mc.setBlock(x+3, y+1, z+5, 1)

	mc.setBlock(x+2, y+0, z+5, 1)
	mc.setBlock(x+2, y+3, z+5, 1)
	mc.setBlock(x+2, y+2, z+5, 1)
	mc.setBlock(x+2, y+1, z+5, 1)

	mc.setBlock(x+1, y+0, z+5, 1)
	mc.setBlock(x+1, y+3, z+5, 1)
	mc.setBlock(x+1, y+2, z+5, 1)
	mc.setBlock(x+1, y+1, z+5, 1)

	mc.setBlock(x+0, y+0, z+5, 1)
	mc.setBlock(x+0, y+3, z+5, 1)
	mc.setBlock(x+0, y+2, z+5, 1)
	mc.setBlock(x+0, y+1, z+5, 1)

	mc.setBlock(x+2, y-1, z+4, 1)
	mc.setBlock(x+2, y-1, z+3, 1)
	mc.setBlock(x+2, y-1, z+2, 1)
	mc.setBlock(x+2, y-1, z+1, 1)

	mc.setBlock(x+1, y-1, z+4, 1)
	mc.setBlock(x+1, y-1, z+3, 1)
	mc.setBlock(x+1, y-1, z+2, 1)
	mc.setBlock(x+1, y-1, z+1, 1)

	mc.setBlock(x+3, y-1, z+4, 1)
	mc.setBlock(x+3, y-1, z+3, 1)
	mc.setBlock(x+3, y-1, z+2, 1)
	mc.setBlock(x+3, y-1, z+1, 1)

	mc.setBlock(x+4, y-1, z+4, 1)
	mc.setBlock(x+4, y-1, z+3, 1)
	mc.setBlock(x+4, y-1, z+2, 1)
	mc.setBlock(x+4, y-1, z+1, 1)

	mc.setBlock(x+2, y+5, z+4, 1)
	mc.setBlock(x+2, y+5, z+3, 1)
	mc.setBlock(x+2, y+5, z+2, 1)
	mc.setBlock(x+2, y+5, z+1, 1)

	mc.setBlock(x+1, y+5, z+4, 1)
	mc.setBlock(x+1, y+5, z+3, 1)
	mc.setBlock(x+1, y+5, z+1, 1)

	mc.setBlock(x+3, y+5, z+4, 1)
	mc.setBlock(x+3, y+5, z+3, 1)
	mc.setBlock(x+3, y+5, z+2, 1)
	mc.setBlock(x+3, y+5, z+1, 1)

	mc.setBlock(x+4, y+5, z+4, 1)
	mc.setBlock(x+4, y+5, z+3, 1)
	mc.setBlock(x+4, y+5, z+2, 1)
	mc.setBlock(x+4, y+5, z+1, 1)

	mc.setBlock(x+4, y+6, z+4, 1)
	mc.setBlock(x+4, y+6, z+3, 1)
	mc.setBlock(x+4, y+6, z+2, 1)
	mc.setBlock(x+4, y+6, z+1, 1)


	mc.setBlock(x-1, y, z, 1)
	mc.setBlock(x, y, z, 1)
	mc.setBlock(x, y, z-1, 1)
	mc.setBlock(x-2, y, z, 1)
	mc.setBlock(x, y, z-2, 1)
	mc.setBlock(x-3, y, z, 1)
	mc.setBlock(x, y, z-3, 1)
	mc.setBlock(x-4, y, z, 1)
	mc.setBlock(x, y, z-4, 1)

	mc.setBlock(x-5, y+1, z, 1)
	mc.setBlock(x-5, y+1, z, 1)
	mc.setBlock(x-5, y+1, z+1, 1)
	mc.setBlock(x-2, y+1, z, 1)
	mc.setBlock(x, y+1, z+2, 1)
	mc.setBlock(x-3, y+1, z, 1)
	mc.setBlock(x, y+1, z+3, 1)
	mc.setBlock(x-4, y+1, z, 1)
	mc.setBlock(x, y+1, z+4, 1)

	mc.setBlock(x-1, y+2, z, 1)
	mc.setBlock(x, y+2, z, 1)
	mc.setBlock(x, y+2, z+1, 1)
	mc.setBlock(x-2, y+2, z, 1)
	mc.setBlock(x, y+2, z+2, 1)
	mc.setBlock(x-3, y+2, z, 1)
	mc.setBlock(x, y+2, z+3, 1)
	mc.setBlock(x-4, y+2, z, 1)
	mc.setBlock(x, y+2, z+4, 1)

	mc.setBlock(x-1, y+3, z, 1)
	mc.setBlock(x, y+3, z, 1)
	mc.setBlock(x, y+3, z+1, 1)
	mc.setBlock(x-2, y+3, z, 1)
	mc.setBlock(x, y+3, z+2, 1)
	mc.setBlock(x-3, y+3, z, 1)
	mc.setBlock(x, y+3, z+3, 1)
	mc.setBlock(x-4, y+3, z, 1)
	mc.setBlock(x, y+3, z+4, 1)


	mc.setBlock(x-5, y, z, 1)
	mc.setBlock(x-5, y, z, 1)
	mc.setBlock(x-5, y, z+1, 1)
	mc.setBlock(x-5, y, z, 1)
	mc.setBlock(x-5, y, z+2, 1)
	mc.setBlock(x-5, y, z, 1)
	mc.setBlock(x-5, y, z+3, 1)
	mc.setBlock(x-5, y, z, 1)
	mc.setBlock(x-5, y, z+4, 1)

	mc.setBlock(x-5, y+1, z, 1)
	mc.setBlock(x-5, y+1, z, 1)
	mc.setBlock(x-5, y+1, z+1, 1)
	mc.setBlock(x-5, y+1, z, 1)
	mc.setBlock(x-5, y+1, z+2, 1)
	mc.setBlock(x-5, y+1, z, 1)
	mc.setBlock(x-5, y+1, z+3, 1)
	mc.setBlock(x-5, y+1, z, 1)
	mc.setBlock(x-5, y+1, z+4, 1)

	mc.setBlock(x-5, y+2, z, 1)
	mc.setBlock(x-5, y+2, z, 1)
	mc.setBlock(x-5, y+2, z+1, 1)
	mc.setBlock(x-5, y+2, z, 1)
	mc.setBlock(x-5, y+2, z+2, 1)
	mc.setBlock(x-5, y+2, z, 1)
	mc.setBlock(x-5, y+2, z+3, 1)
	mc.setBlock(x-5, y+2, z, 1)
	mc.setBlock(x-5, y+2, z+4, 1)

	mc.setBlock(x-5, y+3, z, 1)
	mc.setBlock(x-5, y+3, z, 1)
	mc.setBlock(x-5, y+3, z+1, 1)
	mc.setBlock(x-5, y+3, z, 1)
	mc.setBlock(x-5, y+3, z+2, 1)
	mc.setBlock(x-5, y+3, z, 1)
	mc.setBlock(x-5, y+3, z+3, 1)
	mc.setBlock(x-5, y+3, z, 1)
	mc.setBlock(x-5, y+3, z+4, 1)

	mc.setBlock(x-5, y+0, z+5, 1)
	mc.setBlock(x-5, y+3, z+5, 1)
	mc.setBlock(x-5, y+2, z+5, 1)
	mc.setBlock(x-5, y+1, z+5, 1)

	mc.setBlock(x-5, y+0, z+4, 1)
	mc.setBlock(x-5, y+3, z+4, 1)
	mc.setBlock(x-5, y+2, z+4, 1)
	mc.setBlock(x-5, y+1, z+4, 1)

	mc.setBlock(x-5, y+0, z+3, 1)
	mc.setBlock(x-5, y+3, z+3, 1)
	mc.setBlock(x-5, y+2, z+3, 1)
	mc.setBlock(x-5, y+1, z+3, 1)

	mc.setBlock(x-5, y+0, z+2, 1)
	mc.setBlock(x-5, y+3, z+2, 1)
	mc.setBlock(x-5, y+2, z+2, 1)
	mc.setBlock(x-5, y+1, z+2, 1)

	mc.setBlock(x-5, y+0, z+1, 1)
	mc.setBlock(x-5, y+3, z+1, 1)
	mc.setBlock(x-5, y+2, z+1, 1)
	mc.setBlock(x-5, y+1, z+1, 1)

	mc.setBlock(x-4, y+0, z+5, 1)
	mc.setBlock(x-4, y+3, z+5, 1)
	mc.setBlock(x-4, y+2, z+5, 1)
	mc.setBlock(x-4, y+1, z+5, 1)

	mc.setBlock(x-3, y+0, z+5, 1)
	mc.setBlock(x-3, y+3, z+5, 1)
	mc.setBlock(x-3, y+2, z+5, 1)
	mc.setBlock(x-3, y+1, z+5, 1)

	mc.setBlock(x-2, y+0, z+5, 1)
	mc.setBlock(x-2, y+3, z+5, 1)
	mc.setBlock(x-2, y+2, z+5, 1)
	mc.setBlock(x-2, y+1, z+5, 1)

	mc.setBlock(x-1, y+0, z+5, 1)
	mc.setBlock(x-1, y+3, z+5, 1)
	mc.setBlock(x-1, y+2, z+5, 1)
	mc.setBlock(x-1, y+1, z+5, 1)

	mc.setBlock(x-0, y+0, z+5, 1)
	mc.setBlock(x-0, y+3, z+5, 1)
	mc.setBlock(x-0, y+2, z+5, 1)
	mc.setBlock(x-0, y+1, z+5, 1)

	mc.setBlock(x-2, y-1, z+4, 1)
	mc.setBlock(x-2, y-1, z+3, 1)
	mc.setBlock(x-2, y-1, z+2, 1)
	mc.setBlock(x-2, y-1, z+1, 1)

	mc.setBlock(x-1, y-1, z+4, 1)
	mc.setBlock(x-1, y-1, z+3, 1)
	mc.setBlock(x-1, y-1, z+2, 1)
	mc.setBlock(x-1, y-1, z+1, 1)

	mc.setBlock(x-3, y-1, z+4, 1)
	mc.setBlock(x-3, y-1, z+3, 1)
	mc.setBlock(x-3, y-1, z+2, 1)
	mc.setBlock(x-3, y-1, z+1, 1)

	mc.setBlock(x-4, y-1, z+4, 1)
	mc.setBlock(x-4, y-1, z+3, 1)
	mc.setBlock(x-4, y-1, z+2, 1)
	mc.setBlock(x-4, y-1, z+1, 1)

	mc.setBlock(x-2, y+5, z+4, 1)
	mc.setBlock(x-2, y+5, z+3, 1)
	mc.setBlock(x-2, y+5, z+2, 1)
	mc.setBlock(x-2, y+5, z+1, 1)

	mc.setBlock(x-1, y+5, z+4, 1)
	mc.setBlock(x-1, y+5, z+3, 1)
	mc.setBlock(x-1, y+5, z+1, 1)

	mc.setBlock(x-3, y+5, z+4, 1)
	mc.setBlock(x-3, y+5, z+3, 1)
	mc.setBlock(x-3, y+5, z+2, 1)
	mc.setBlock(x-3, y+5, z+1, 1)
	
	mc.setBlock(x-4, y+5, z+4, 1)
	mc.setBlock(x-4, y+5, z+3, 1)
	mc.setBlock(x-4, y+5, z+2, 1)
	mc.setBlock(x-4, y+5, z+1, 1)

	mc.setBlock(x-4, y+6, z+4, 1)
	mc.setBlock(x-4, y+6, z+3, 1)
	mc.setBlock(x-4, y+6, z+2, 1)
	mc.setBlock(x-4, y+6, z+1, 1)


    
def main():

	mc = init()
	mc.postToChat("Hello My Bruddas!!!!!!!")
	x, y, z = mc.player.getTilePos()                                                  
	#x, y, z = mc.player.getPos()
	xs,ys,zs = x,y,z+10
	building(mc,xs,ys,zs)
	mc.player.setPos(xs,ys,zs)   
	
main()
